<?xml version="1.0"?>
<sdf version='1.5'>
  <model name='plane'>
    <static>false</static>
    <pose>0 0 1 0 0 0</pose>
    <link name='base_link'>
      <pose>0 0 0 0 0 0</pose>
      <inertial>
        <pose>0 0 0 0 0 0</pose>
        <mass>0.28</mass>
        <inertia>
          <ixx>0.197563</ixx>
          <ixy>0</ixy>
          <ixz>0</ixz>
          <iyy>0.1458929</iyy>
          <iyz>0</iyz>
          <izz>0.1477</izz>
        </inertia>
      </inertial>
      <collision name='base_link_collision'>
        <geometry>
          <box>
            <size>0.3 0.1 0.1</size>
          </box>
        </geometry>
      </collision>
      <visual name='base_link_visual'>
        <geometry>
          <box>
            <size>0.3 0.1 0.1</size>
          </box>
        </geometry>
      </visual>
    </link>

    <joint name='left_wing_joint' type='revolute'>
      <child>left_wing</child>
      <parent>base_link</parent>
      <pose>0.00 -0.205 0 0 0 0</pose>
      <axis>
        <xyz>1 0 0</xyz>
        <limit>
          <lower>-0.3</lower>
          <upper>0.3</upper>
        </limit>
        <dynamics>
          <damping>1.000</damping>
        </dynamics>
      </axis>
      <physics>
        <ode>
          <implicit_spring_damper>1</implicit_spring_damper>
        </ode>
      </physics>
    </joint>
    <link name='left_wing'>
      <pose>0.05 0.25 0.05 0 0 0</pose>
      <inertial>
        <pose>0 0 0 0 0 0</pose>
        <mass>0.01</mass>
        <inertia>
          <ixx>0.197563</ixx>
          <ixy>0</ixy>
          <ixz>0</ixz>
          <iyy>0.1458929</iyy>
          <iyz>0</iyz>
          <izz>0.1477</izz>
        </inertia>
      </inertial>
      <collision name='left_wing_collision'>
        <geometry>
          <box>
            <size>0.1 0.4 0.01</size>
          </box>
        </geometry>
      </collision>
      <visual name='left_wing_visual'>
        <geometry>
          <box>
            <size>0.1 0.4 0.01</size>
          </box>
        </geometry>
      </visual>
    </link>
    <joint name='right_wing_joint' type='revolute'>
      <child>right_wing</child>
      <parent>base_link</parent>
      <pose>0.00 0.205 0 0 0 0</pose>
      <axis>
        <xyz>1 0 0</xyz>
        <limit>
          <lower>-10</lower>
          <upper>10</upper>
        </limit>
        <dynamics>
          <damping>1.000</damping>
        </dynamics>
      </axis>
      <physics>
        <ode>
          <implicit_spring_damper>1</implicit_spring_damper>
        </ode>
      </physics>
    </joint>
    <link name='right_wing'>
      <pose>0.05 -0.25 0.05 0 0 0</pose>
      <inertial>
        <pose>0 0 0 0 0 0</pose>
        <mass>0.01</mass>
        <inertia>
          <ixx>0.00003</ixx>
          <ixy>0</ixy>
          <ixz>0</ixz>
          <iyy>0.001</iyy>
          <iyz>0</iyz>
          <izz>0.0000001</izz>
        </inertia>
      </inertial>
      <collision name='right_wing_collision'>
        <geometry>
          <box>
            <size>0.1 0.4 0.01</size>
          </box>
        </geometry>
      </collision>
      <visual name='right_wing_visual'>
        <geometry>
          <box>
            <size>0.1 0.4 0.01</size>
          </box>
        </geometry>
      </visual>
    </link>
   <plugin name='flap' filename='libgazebo_flapping_control.so'>
      <robotNamespace></robotNamespace>
      <leftwing>left_wing_joint</leftwing>
      <rightwing>right_wing_joint</rightwing>
      <amplitude>0.3</amplitude>
      <wingspan>1.2</wingspan>
      <a0>0.05984281113</a0>
      <lcp>-0.05 0.1 0.05</lcp>
      <rcp>-0.05 -0.1 0.05</rcp>
      <twist>0.05</twist>
      <chord>0.225</chord>
      <link_name>base_link</link_name>
      <frequency>8</frequency>
      <forward>1 0 0</forward>
      <upward>0 0 1</upward>
      <rho>1.295</rho>
      <radial_symmetry>0</radial_symmetry>
   </plugin>
  </model>
</sdf>
